<?xml version="1.0"?>

<robot xmlns:xacro="http://www.ros.org/wiki/xacro" 
 	xmlns:sensor="http://playerstage.sourceforge.net/gazebo/xmlschema/#sensor"
    	xmlns:controller="http://playerstage.sourceforge.net/gazebo/xmlschema/#controller"
    	xmlns:interface="http://playerstage.sourceforge.net/gazebo/xmlschema/#interface"
	name="robot1_xacro">


	<xacro:property name="length_wheel" value="0.05" />
	<xacro:property name="radius_wheel" value="0.05" />
	<xacro:macro name="default_inertial" params="mass">
               <inertial>
                       <mass value="${mass}" />
                       <inertia ixx="1.0" ixy="0.0" ixz="0.0"
                                iyy="1.0" iyz="0.0"
                                izz="1.0" />
               </inertial>
	</xacro:macro>

	<link name="base_footprint">
   		<visual>
			<geometry>
      				<box size="0.001 0.001 0.001"/>
     		</geometry>
			<origin rpy="0 0 0" xyz="0 0 0"/>
   		</visual>
		<xacro:default_inertial mass="0.0001"/>
 	</link>

	<gazebo reference="base_footprint">
		<material>Gazebo/Green</material>
		<turnGravityOff>false</turnGravityOff>
	</gazebo>

	<joint name="base_footprint_joint" type="fixed">
		<origin xyz="0 0 0" />
		<parent link="base_footprint" />
		<child link="base_link" />
	</joint>


	<link name="base_link">
   		<visual>
			<geometry>
      				<mesh filename="package://dashan_description/mesh/body.dae"/>
     		</geometry>
			<origin rpy="0 0 0" xyz="0 0 0"/>
   		</visual>
 	</link>

 	<link name="wheel_1">
   		<visual>
     			<geometry>
       				<mesh filename="package://dashan_description/mesh/wheel.dae"/>
     			</geometry>
			<origin rpy="0 0 0" xyz="0 0 0"/>			
		</visual>
 	</link>

 	<link name="wheel_2">
   		<visual>
     			<geometry>
       				<mesh filename="package://dashan_description/mesh/wheel.dae"/>
     			</geometry>
			<origin rpy="0 0 0" xyz="0 0 0"/>			
		</visual>
 	</link>
    
 	<link name="wheel_3">
   		<visual>
     			<geometry>
       				<mesh filename="package://dashan_description/mesh/wheel.dae"/>
     			</geometry>
			<origin rpy="0 0 0" xyz="0 0 0"/>			
		</visual>
 	</link>

 	<link name="wheel_4">
   		<visual>
     			<geometry>
       				<mesh filename="package://dashan_description/mesh/wheel.dae"/>
     			</geometry>
			<origin rpy="0 0 0" xyz="0 0 0"/>			
		</visual>
 	</link>

	<link name="camera_rgb_frame"/>

	<link name="camera_link">
    		<visual>
      			<origin rpy="0 0 1.57079632679" xyz="0 0 0"/>
      			<geometry>
        			<mesh filename="package://dashan_description/mesh/kinect.dae"/>
			    </geometry>
    		</visual>	
  	</link>

	<link name="camera_depth_frame"/>



 <joint name="base_to_wheel1" type="continuous">
   <parent link="base_link"/>
   <child link="wheel_1"/>
   <origin rpy="0 0 0" xyz="0.15 0.1875 -0.0205"/>
   <axis xyz="0 0 1" />
 </joint>

 <joint name="base_to_wheel2" type="continuous">
   <axis xyz="0 0 1" />
   <parent link="base_link"/>
   <child link="wheel_2"/>
   <origin rpy="0 0 0" xyz="-0.15 0.1875 -0.0205"/>
</joint>

 <joint name="base_to_wheel3" type="continuous">
   <parent link="base_link"/>
   <axis xyz="0 0 1" />
   <child link="wheel_3"/>
   <origin rpy="0 0 0" xyz="0.15 -0.1875 -0.0205"/>
 </joint>

 <joint name="base_to_wheel4" type="continuous">
   <parent link="base_link"/>
   <axis xyz="0 0 1" />
   <child link="wheel_4"/>
   <origin rpy="0 0 0" xyz="-0.15 -0.1875 -0.0205"/>
 </joint>

 <joint name="camera_rgb_joint" type="fixed">
    <origin rpy="0 0 0" xyz="0.18 0 0.05"/>
    <parent link="base_link"/>
    <child link="camera_rgb_frame"/>
 </joint>

 <joint name="camera_joint" type="fixed">
    <origin rpy="0 0 0" xyz="-0.031 0.0125 -0.016"/>
    <parent link="camera_rgb_frame"/>
    <child link="camera_link"/>
  </joint>

  <joint name="camera_depth_joint" type="fixed">
    <origin rpy="0 0 0" xyz="0 0.025 0"/>
    <parent link="camera_rgb_frame"/>
    <child link="camera_depth_frame"/>
  </joint>

</robot>
