<?xml version="1.0"?>

<robot xmlns:xacro="http://www.ros.org/wiki/xacro" 
 	xmlns:sensor="http://playerstage.sourceforge.net/gazebo/xmlschema/#sensor"
    	xmlns:controller="http://playerstage.sourceforge.net/gazebo/xmlschema/#controller"
    	xmlns:interface="http://playerstage.sourceforge.net/gazebo/xmlschema/#interface"
	name="robot1_xacro">


	<xacro:property name="length_wheel" value="0.05" />
	<xacro:property name="radius_wheel" value="0.05" />
	<xacro:macro name="default_inertial" params="mass">
               <inertial>
                       <mass value="${mass}" />
                       <inertia ixx="1.0" ixy="0.0" ixz="0.0"
                                iyy="1.0" iyz="0.0"
                                izz="1.0" />
               </inertial>
	</xacro:macro>

	<link name="base_footprint">
   		<visual>
			<geometry>
      				<box size="0.001 0.001 0.001"/>
     		</geometry>
			<origin rpy="0 0 0" xyz="0 0 0"/>
   		</visual>
		<xacro:default_inertial mass="0.0001"/>
 	</link>

	<gazebo reference="base_footprint">
		<material>Gazebo/Green</material>
		<turnGravityOff>false</turnGravityOff>
	</gazebo>

	<joint name="base_footprint_joint" type="fixed">
		<origin xyz="0 0 0.2775" />
		<parent link="base_footprint" />
		<child link="base_link" />
	</joint>


	<link name="base_link">
   		<visual>
			<geometry>
					<box size="0.85 0.57 0.305"/>
     		</geometry>
			<material name="black">    
                <color rgba="0 0 0 .5" />   
            </material>   
			<origin rpy="0 0 0" xyz="0 0 0"/>
   		</visual>
 	</link>

 	<link name="wheel_1">
   		<visual>
     			<geometry>
				    <cylinder length="0.105" radius="0.155">
					</cylinder>  
     			</geometry>
				<material name="yellow">    
                    <color rgba="1 1 0 0.5"/>    
                </material>
			<origin rpy="0 0 0" xyz="0 0 -0.0525"/>			
		</visual>
 	</link>

 	<link name="wheel_2">
   		<visual>
     			<geometry>
       				<cylinder length="0.105" radius="0.155">
					</cylinder>
     			</geometry>
				<material name="yellow">    
                    <color rgba="1 1 0 0.5"/>    
                </material>
			<origin rpy="0 0 0" xyz="0 0 -0.0525"/>			
		</visual>
 	</link>
    
 	<link name="wheel_3">
   		<visual>
     		<geometry>
       			<cylinder length="0.105" radius="0.155">
				</cylinder>
     		</geometry>
				<material name="yellow">    
                    <color rgba="1 1 0 0.5"/>    
                </material>
			<origin rpy="0 0 0" xyz="0 0 0.0525"/>			
		</visual>
 	</link>

 	<link name="wheel_4">
   		<visual>
     		<geometry>
       			<cylinder length="0.105" radius="0.155">
				</cylinder>
     		</geometry>
				<material name="yellow">    
                    <color rgba="1 1 0 0.5"/>    
                </material>
			<origin rpy="0 0 0" xyz="0 0 0.0525"/>			
		</visual>
 	</link>

<!-- comment camera_link when i use rplidar -->
<!--
	<link name="camera_link">
    		<visual>
      			<origin rpy="0 0 1.57079632679" xyz="0 0 0"/>
      			<geometry>
        			<mesh filename="package://dashan_description/mesh/kinect.dae"/>
			    </geometry>
    		</visual>	
  	</link>
-->

 <link name="mynteye_link_frame">
    		<visual>
      			<geometry>
                               <box size="0.165 0.0315 0.0296"/>
			</geometry>
                        <material name="white">
                          <color rgba="1 1 1 .5" />
                        </material>
                        <origin rpy="0 0 1.57079632679" xyz="0 0 0"/>
    		</visual>	
 </link>
  	
 <joint name="base_to_wheel1" type="continuous">
   <parent link="base_link"/>
   <child link="wheel_1"/>
   <origin rpy="1.57075 0 0" xyz="0.24 0.305 -0.1205"/>
   <axis xyz="0 0 1" />
 </joint>

 <joint name="base_to_wheel2" type="continuous">
   <parent link="base_link"/>
   <child link="wheel_2"/>
   <origin rpy="1.57075 0 0" xyz="-0.24 0.305 -0.1205"/>
   <axis xyz="0 0 1" />
</joint>

 <joint name="base_to_wheel3" type="continuous">
   <parent link="base_link"/>
   <child link="wheel_3"/>
   <origin rpy="1.57075 0 0" xyz="0.24 -0.305 -0.1205"/>
   <axis xyz="0 0 1" />
 </joint>

 <joint name="base_to_wheel4" type="continuous">
   <parent link="base_link"/>
   <child link="wheel_4"/>
   <origin rpy="1.57075 0 0" xyz="-0.24 -0.305 -0.1205"/>
    <axis xyz="0 0 1" />
 </joint>

<!-- comment camera_link when i use rplidar -->
<!--
 <joint name="camera_link_joint" type="fixed">
    <origin rpy="0 0 0" xyz="0.2 0 0.05"/>
    <parent link="base_link"/>
    <child link="camera_link"/>
 </joint>
-->
  <joint name="mynteye_joint" type="fixed">
    <origin rpy="0 0 0" xyz="0.36225 0.0025 0.1402"/>
    <parent link="base_link"/>
    <child link="mynteye_link_frame"/>
 </joint>
 
</robot>
